Workbook

Sheet Kickoff Questions
B1: USABILITY TEST KICKOFF · Questions to Scope Your Study
C2: Question | D2: Your Notes
C3: Background & Organizational Context
B4: › | C4: What is the product or page, and who is it designed for? | D4: https://ircc.canada.ca/english/newcomers/services/index.asp Designed for newcomers to Canada seeking services
B5: › | C5: What problem does it solve for our web visitors? What problem does it solve for the IRCC?
B6: › | C6: Where does this sit in the design lifecycle — pre-launch validation, a post-launch audit, or something else? | D6: Post-launch audit + validation of recent design updates
B7: › | C7: What prompted this research request right now? Was there a specific incident, metric, complaint, or upcoming deadline?
B8: › | C8: Has this product or feature been tested before? If so, what were the findings, and what changed since then?
B9: › | C9: Are there competing internal priorities or other work we should be aware of that might affect timelines?
C11: Research Goals & Questions
B12: › | C12: What are the two or three most important things you need to learn from this test? | D12: o Can users filter services that are relevant to them? Maybe this is too expansive, but I’d love to see some mobile and desktop sessions. o Are French-speaking users having any specific issues with the page, including users destined for or living  Outside Quebec  In Quebec (i.e. does the expand collapse work effectively divert Quebec’s newcomers to MIFI) o I’m also debating whether we want to check if clients understand the new eligibility criteria for economic immigrants?  This would potentially add a second page to our testing, and it’s not as much of a priority for me
B13: › | C13: If you could only answer one question from this test, what would it be?
B14: › | C14: What decisions will be made with the output of this test?
B15: › | C15: Are there any hypotheses you're already working with — things you suspect are true but need to validate or disprove?
B16: › | C16: Are there any areas of the product you specifically want to include or exclude from testing?
B17: › | C17: Is there anything you're worried we might find?
B18: › | C18: What does 'success' look like for this test — what would make you or your stakeholders feel it was worth doing?
C20: Users & Participants
B21: › | C21: Who is the primary target user for this product or feature?
B22: › | C22: Are there distinct user segments or personas we should account for? Should we test all of them, or prioritize one?
B23: › | C23: What level of prior experience with this product should participants have — first-time users, occasional users, power users, or a mix?
B24: › | C24: Are there any technical or domain knowledge requirements for participants (e.g., must be a healthcare professional, must manage a team of 5+)?
B25: › | C25: What devices do your users typically use — desktop, mobile, tablet? Is there a known split?
B26: › | C26: What is the geographic and language distribution of your users? Should the test reflect that?
B27: › | C27: Are there demographics that are particularly important to include or exclude (e.g., accessibility needs, age ranges, tech literacy)?
C29: Scope & Tasks
B30: › | C30: What are the specific tasks or user journeys you want us to test?
B31: › | C31: Are these tasks based on actual observed user behaviour, or are they assumed flows?
B32: › | C32: What is the starting point for each task — a specific URL, a particular app state, a logged-in or logged-out experience?
B33: › | C33: Are there prerequisite conditions for any tasks (e.g., the user must have already created an account, already applied for a visa)?
B34: › | C34: Are there tasks you want to include for benchmarking purposes — things you've tested before and want to track over time?
B35: › | C35: What does successful completion of each task look like? Is it binary, or is partial completion meaningful?
B36: › | C36: Should we be testing the current live product, a prototype, or a staging environment?
B37: › | C37: If it's a prototype — how complete is it? Are there dead ends, missing states, or known gaps we should know about?
B38: › | C38: Are there any flows that are broken, incomplete, or should be avoided during testing?
C41: Timeline & Logistics
B42: › | C42: When do you need findings delivered by? Is there a specific decision gate, release date, or meeting this needs to feed into?
B43: › | C43: Working backwards from that — what is the latest we can start recruitment?
B44: › | C44: How much flexibility is there in the timeline if recruitment is slow or technical issues arise?
B45: › | C45: What is the availability of your team to review screeners, discussion guides, and prototypes before fieldwork begins?
...

Sheet Summary
B1: USABILITY TEST PLAN · Summary Dashboard
B2: TASK COMPLETION RATES (by Success Code)
B3: Metric | C3: Task 1 | D3: Task 2 | E3: Task 3 | F3: Task 4 | G3: Task 5
B4: Success | C4: =COUNTIF(Data!C5:C194,"Success") -> 0 | D4: =COUNTIF(Data!F5:F19,"Success") -> 0 | E4: =COUNTIF(Data!I5:I19,"Success") -> 0 | F4: =COUNTIF(Data!L5:L19,"Success") -> 0 | G4: =COUNTIF(Data!O5:O19,"Success") -> 0
B5: Partial Fail | C5: =COUNTIF(Data!C5:C19,"Partial Fail") -> 0 | D5: =COUNTIF(Data!F5:F19,"Partial Fail") -> 0 | E5: =COUNTIF(Data!I5:I19,"Partial Fail") -> 0 | F5: =COUNTIF(Data!L5:L19,"Partial Fail") -> 0 | G5: =COUNTIF(Data!O5:O19,"Partial Fail") -> 0
B6: Fail | C6: =COUNTIF(Data!C5:C19,"Fail") -> 0 | D6: =COUNTIF(Data!F5:F19,"Fail") -> 0 | E6: =COUNTIF(Data!I5:I19,"Fail") -> 0 | F6: =COUNTIF(Data!L5:L19,"Fail") -> 0 | G6: =COUNTIF(Data!O5:O19,"Fail") -> 0
B7: Time Limit | C7: =COUNTIF(Data!C5:C19,"Time Limit") -> 0 | D7: =COUNTIF(Data!F5:F19,"Time Limit") -> 0 | E7: =COUNTIF(Data!I5:I19,"Time Limit") -> 0 | F7: =COUNTIF(Data!L5:L19,"Time Limit") -> 0 | G7: =COUNTIF(Data!O5:O19,"Time Limit") -> 0
B8: Give Up | C8: =COUNTIF(Data!C5:C19,"Give Up") -> 0 | D8: =COUNTIF(Data!F5:F19,"Give Up") -> 0 | E8: =COUNTIF(Data!I5:I19,"Give Up") -> 0 | F8: =COUNTIF(Data!L5:L19,"Give Up") -> 0 | G8: =COUNTIF(Data!O5:O19,"Give Up") -> 0
B9: Technical Issues | C9: =COUNTIF(Data!C5:C19,"Technical Issues") -> 0 | D9: =COUNTIF(Data!F5:F19,"Technical Issues") -> 0 | E9: =COUNTIF(Data!I5:I19,"Technical Issues") -> 0 | F9: =COUNTIF(Data!L5:L19,"Technical Issues") -> 0 | G9: =COUNTIF(Data!O5:O19,"Technical Issues") -> 0
B10: Other | C10: =COUNTIF(Data!C5:C19,"Other") -> 0 | D10: =COUNTIF(Data!F5:F19,"Other") -> 0 | E10: =COUNTIF(Data!I5:I19,"Other") -> 0 | F10: =COUNTIF(Data!L5:L19,"Other") -> 0 | G10: =COUNTIF(Data!O5:O19,"Other") -> 0
B11: Total Recorded | C11: =COUNTA(Data!C5:C19) -> 0 | D11: =COUNTA(Data!F5:F19) -> 0 | E11: =COUNTA(Data!I5:I19) -> 0 | F11: =COUNTA(Data!L5:L19) -> 0 | G11: =COUNTA(Data!O5:O19) -> 0
B12: Success Rate | C12: =IFERROR(COUNTIF(Data!C5:C19,"Success")/COUNTA(Data!C5:C19),"") | D12: =IFERROR(COUNTIF(Data!F5:F19,"Success")/COUNTA(Data!F5:F19),"") | E12: =IFERROR(COUNTIF(Data!I5:I19,"Success")/COUNTA(Data!I5:I19),"") | F12: =IFERROR(COUNTIF(Data!L5:L19,"Success")/COUNTA(Data!L5:L19),"") | G12: =IFERROR(COUNTIF(Data!O5:O19,"Success")/COUNTA(Data!O5:O19),"")
B14: TOP-LEVEL FINDINGS SUMMARY
B15: Most Critical Issue
B16: Most Impacted Task
B17: Overall Success Rate | C17: =IFERROR(AVERAGE(C13:G13),"")
B18: Key Recommendation 1
B19: Key Recommendation 2
B20: Key Recommendation 3
B21: Follow-up Questions
B22: Next Steps
C35: Are there prerequisite conditions for any tasks (e.g., the user must have already created an account, already applied for a visa)?
C53: Who are the key stakeholders for this project?
C55: Does anyone need to approve the screener, tasks, and final deliverable?
C56: Are there known internal disagreements about the design we should be aware of — areas where the team is already debating what to do?

Sheet Test Goals
B1: USABILITY TEST PLAN · Test Goals
B2: STUDY METADATA
B3: Study Title | C3: Newcomer Services Tool Usability Test
B4: Page or Product | C4: https://ircc.canada.ca/francais/nouveaux/services/index.asp
B5: Research Lead | C5: Eric
B6: WUX Support | C6: Nadya
B7: Date(s) of Testing | C7: April 27 - May 22
B8: Methodology | C8: Unmoderated Usability Testing (UserLytics); French participants; mix of mobile and desktop
B10: STUDY GOALS
B11: # | C11: Research Goal | D11: Why It Matters | E11: How It Will Be Measured | F11: Priority
B12: 1 | C12: Assess usability of search filters; AND OR logic; etc. Search and filter button distance, etc. Do people understand that results are sorted closest to furthest? | D12: Key function of page; recently redesigned | E12: For filter task(s), we will track: Do people Find them? Do people Use them? Do they encounter Errors? Do they understand the output of the filters? | F12: High
B13: 2 | C13: Explore pain points for FR participants in tasks both outside Canada and Inside Quebec | D13: Important to divert QC-related queries; recently redesigned | E13: Task success - do participants successfully understand where to go if they are in Quebec or not? Possibly two tasks - outside canada looking for pre-arrival, but also outside canada with intention for a speicific community. | F13: High
B14: 3 | C14: Assess usability of economic migrant criteria | D14: Recently updated - would be nice to get some info about performance | E14: Task success + qualitative feedback | F14: Low
B15: 4 | C15: program client needs: different provinces sometimes come up when searching just by province; Reseau Femmes appearing when you search Vancouver + French; | F15: Low
B16: 5 | C16: context: SPO tool has list of 1300 orgs, only 206 are franco services. FR page: 54% only use location, not filters.
B18: MEASUREMENT METHODS · Reference
B19: Metric | C19: Description | D19: When to Use
B20: Time on Task | C20: Task time within UserLytics | D20: Efficiency benchmarking; identifying slow flows
B21: Task Success Rate | C21: % of participants who complete task successfully | D21: Core usability health metric
B22: Error Rate | C22: # of errors / incorrect actions per task attempt | D22: Identifying misleading UI elements
B23: Think-Aloud Feedback | C23: Verbal commentary captured during the session | D23: Understanding mental models & confusion points

Sheet Tasks
B1: USABILITY TEST PLAN · Tasks & Scenarios
B2: Define each task scenario, the starting state, success criteria, and researcher notes.
B3: Task # | C3: Task Title | D3: Task Text English (for easier drafting) | E3: Task Text French (shown to participant) | F3: Success Criteria | G3: Starting URL / Pre-conditions | H3: Time Limit (mm:ss) | I3: Difficulty Estimate | J3: Researcher Notes
B4: T1 | C4: Basic Filter Task | D4: You are a permanent resident of Canada, living in Manitoba. Where could you go to get support for your 16 year old son, who only speaks French? | E4: Vous êtes résident permanent du Canada, vivant au Manitoba. Où pourriez-vous aller pour obtenir du soutien pour votre fils de 16 ans, qui ne parle que français ? | F4: Success: Filters: Uses In French; Youth (15-30) Search: Manitoba Answer: Pluri-elles (Manitoba), inc.OR CDEM OR they identify a Manitoba SPO that fits criteria without using filters Partial success: -Identifies a SPO that doesn't provide service in French OR doesn't provide supports for youth OR isn't in Manitoba (e.g. 1 thing wrong) Partial fail: 2 or more things wrong Fail: Completely wrong. Did not identify a SPO at all, OR identified one that isn't French, doesn't provide services for youth, and isn't in Manitoba | G4: SPO tool, anchored to top of page. | H4: 5 mins | I4: Medium | J4: Goal: Evaluate usage of filters and search Subgoal: Does participant say anything when the results include other provinces?
B5: T2 | C5: Inside QC task | D5: You are a refugee living in Gatineau, Quebec. Where could you go to get support to find housing? | E5: Vous êtes un réfugié vivant à Gatineau, au Québec. Où pourriez-vous aller pour obtenir de l'aide afin de trouver un logement ? | F5: Success: Opens QC expando and continues to MIFI site. Identifies this site or any service on it. Partial success: Opens QC expando but doesn't click. Ends task at expando. Partial fail: ??? Fail: Uses SPO tool to search for Quebec
B6: T3 | C6: Outside Canada - Pre-settlement services | D6: You currently live in Cameroon. Your application to become a permanent resident of Canada has been approved, but you have not yet moved there. Find resources to help you prepare to come to Canada while you are still in Cameroon. | E6: Vous vivez actuellement au Cameroun. Votre demande pour devenir résident permanent du Canada a été approuvée, mais vous n'avez pas encore déménagé là-bas. Trouvez des ressources pour vous aider à vous préparer à venir au Canada pendant que vous êtes encore au Cameroun. | F6: Success: Opens 'Si vous êtes à l’extérieur du Canada' expando AND clicks on link to reach Services avant l’arrivée AND verbally confirms that this is where they would go (any subpage on Pre-arrival services = success) Partial success: Opens expando but doesn't click on the link to Pre-arrival. Partial fail: Understands that SPO search isn't for them, but doesn't know where to go. Fail: Uses SPO tool.
B7: T4 | C7: Ideally include in main test, but possibly EXTRA : Outside Canada - Curious about specific community | D7: You currently live in Algeria. Your application to become a permanent resident of Canada has been approved. You want to move to Toronto, Ontario. When you get to Toronto, where could you go to get support for finding employment and learning English? | E7: Vous vivez actuellement en Algérie. Votre demande pour devenir résident permanent du Canada a été approuvée. Vous souhaitez déménager à Toronto, en Ontario. Une fois à Toronto, où pourriez-vous aller pour obtenir de l'aide pour trouver un emploi et apprendre l'anglais ? | F7: Success: Filters: Learning English; Help finding a job Search: Toronto Answer: Any Toronto SPO that includes those two (Finding work + Learning English) OR they identify a Toronto SPO that fits criteria without using filters Partial success: -Identifies a SPO that doesn't provide learning English OR doesn't provide help finding a job OR isn't in Toronto (e.g. 1 thing wrong) Partial fail: 2 or more things wrong Fail: Completely wrong. Did not identify a SPO at all, OR identified one that doesn't teach English, doesn't provide help with finding a job, and isn't in Toronto
B8: T5 | C8: EXTRA TASK: Economic migrant eligibility | D8: You are a permanent resident of Canada. You got your PR status through the Canadian Experience Class program on April 3, 2026. Are you eligible for the services on this page, and if so, for how long? | E8: Vous êtes un résident permanent du Canada. Vous avez obtenu votre statut de RP grâce au programme de l'expérience canadienne le 3 avril 2026. Êtes-vous admissible aux services de cette page, et le cas échéant, pour combien de temps ? | F8: Success: Opens Eligibility expando, clicks Changes, and confirms that they are eligible for 6 years from April 3. Partial success: Opens Eligibility expando, does NOT click Changes. Confirms that PRs are eligible but cannot confirm for how long Partial fail: Does not open Eligibility expando, and guesses that PRs are eligiblity for SPO services Fail: Cannot confirm at all if they are eligible or not.

Sheet Participants
B1: USABILITY TEST PLAN · Participants
B2: Section A: Define screening criteria. Section B: Record recruited participant details.
B3: SECTION A · Desired Participant Profile & Screening Criteria
B4: Target User Group | C4: Franco newcomers to Canada
B5: Age Range | C5: 18-40
B6: Tech Proficiency | C6: Mix
B7: Device Requirement | C7: Half mobile, half desk
B8: Language | C8: French speakers
B9: Location | C9: Mix of inside and outside of Canada (split multiple tests)
B10: Exclusion Criteria | C10: None for now
B11: Sample Size | C11: 12 total: 6 mob, 6 mob. Possibly subidivide between inside and outside Canada
B12: Incentive | C12: Handled by UL
B14: SECTION B · Recruited Participant Details
B15: P # | C15: Name / Code | D15: Age | E15: Country | F15: Device Type | G15: OS | H15: Language | I15: Tech Proficiency | J15: Recruited By | K15: Session Date & Time | L15: Notes
B16: P01
B17: P02
B18: P03
B19: P04
B20: P05
B21: P06
B22: P07
B23: P08
B24: P09
B25: P10
B26: P11

Sheet Data
A1: USABILITY TEST PLAN · Session Data
A2: Record each participant's performance per task. Use the Success Code dropdown for outcome classification.
B3: TASK 1 | E3: TASK 2 | H3: TASK 3 | K3: TASK 4 | N3: TASK 5
A4: P # | B4: Time on Task | C4: Success Code | D4: Observations / Notes | E4: Time on Task | F4: Success Code | G4: Observations / Notes | H4: Time on Task | I4: Success Code | J4: Observations / Notes | K4: Time on Task | L4: Success Code | M4: Observations / Notes | N4: Time on Task | O4: Success Code | P4: Observations / Notes
A5: P01
A6: P02
A7: P03
A8: P04
A9: P05
A10: P06
A11: P07
A12: P08
A13: P09
A14: P10
A15: P11
A16: P12
... A21: SUCCESS CODE LEGEND
A22: Success | B22: Participant completed the task fully and correctly within the time limit. | E22: Partial Fail | F22: Participant completed the task but with significant errors, help, or workarounds.
A23: Fail | B23: Participant did not complete the task and gave an incorrect outcome. | E23: Time Limit | F23: Participant ran out of time before completing the task.
A24: Give Up | B24: Participant abandoned the task of their own volition. | E24: Technical Issues | F24: Session interrupted by a technical problem unrelated to the participant.
A25: Other | B25: Does not fit any other category. Add details in Observations.

Sheet Analysis
B1: USABILITY TEST PLAN · Analysis & Recommendations
B2: Synthesize findings per task. Identify key issues, severity, and actionable recommendations.
B3: Analysis Dimension | C3: Task 1 | D3: Task 2 | E3: Task 3 | F3: Task 4 | G3: Task 5
B4: Key Usability Issues Observed | C4: List specific problems seen across participants. | D4: List specific problems seen across participants. | E4: List specific problems seen across participants. | F4: List specific problems seen across participants. | G4: List specific problems seen across participants.
B5: Frequency
B6: Severity
B7: Root Cause (Hypothesis)
B8: Supporting Quotes / Observations
B9: Recommendations
B10: Priority for Fix
B11: Effort Estimate
B12: Additional Notes
B14: SEVERITY RATING GUIDE
B15: Severity | C15: Definition | D15: Frequency Threshold | E15: Recommended Action
B16: Critical | C16: Prevents task completion; user cannot proceed | D16: ≥ 50% of participants | E16: Fix before launch
B17: High | C17: Causes significant struggle; workaround is painful | D17: ≥ 30% of participants | E17: Fix in next sprint
B18: Medium | C18: Causes confusion or delay but task is completable | D18: ≥ 20% of participants | E18: Schedule for roadmap
B19: Low | C19: Minor annoyance; cosmetic or edge-case issue | D19: < 20% of participants | E19: Backlog / nice-to-have

Sheet Help & Guidance
B1: HELP & GUIDANCE · Best Practices for Usability Testing
B2: A reference guide for each phase of your usability test — practical tips and curated external reading.
B3: All links open in your browser. Tip: use Ctrl+Click (Windows) or Cmd+Click (Mac) to follow hyperlinks in Excel.
B5: Running an Effective Kickoff Meeting
C6: Practical Guidelines | D6: Further Reading
C7: 1. Start with the decision, not the feature Before diving into tasks to test, anchor the whole conversation on what decision this testing will inform. If stakeholders can't name one, that is the first problem to solve. | D7: NNG: Stakeholder Buy-In for UX Research
C8: 2. Send questions in advance Share the kickoff question list 48 hours early. Stakeholders arrive better prepared, meetings run shorter, and you get more considered answers rather than reactive ones. | D8: NNG: Research Learning Spirals
C9: 3. Surface disagreements early If the room can't agree on the top priority research question, document both views rather than forcing false consensus. Unresolved disagreements surface during analysis — better to name them now. | D9: UX Collective: Aligning Stakeholders
C10: 4. Ask 'what would change your mind?' For each goal, ask stakeholders what evidence would cause them to change course. This reveals which questions are genuinely open and which are fishing for validation. | D10: Maze: Research Ops Handbook
C11: 5. Clarify sign-off chains before you leave Confirm who approves the screener, tasks, and final report — and in what order. A missing approval can delay fieldwork by weeks. | D11: ResearchOps Community
C12: 6. Record or take structured notes Assign a dedicated note-taker so the facilitator can stay focused. Review notes within 24 hours while memory is fresh and send a summary back to stakeholders to confirm alignment. | D12: NNG: Documenting UX Research
B14: Defining Effective Study Goals
C15: Practical Guidelines | D15: Further Reading
C16: 1. Distinguish research goals from organizational goals An organizational goal is 'reduce churn'. A research goal is 'understand why users abandon the onboarding flow after step 3'. Usability tests answer research questions, not organizational metrics directly. | D16: NNG: Research Questions vs. Business Goals
C17: 2. Limit yourself to 3-5 goals per study More than five goals usually means the study is trying to do too much. Prioritise ruthlessly. A focused study with clear answers is worth far more than a sprawling one with ambiguous takeaways. | D17: Usability.gov: Planning a Usability Test
C18: 3. Write goals as questions, not statements 'Evaluate the checkout flow' is a topic. 'Can users complete a purchase without assistance in under 4 minutes?' is a testable goal. The question form forces you to think about what evidence you need. | D18: IxDF: Formulating UX Research Goals
C19: 4. Pair every goal with a measurement method For each goal, define up front how you will know if it has been met — task success rate, time on task, error count, qualitative theme, or a scale score. Unmeasured goals are just intentions. | D19: NNG: Measuring Usability
C20: 5. Get stakeholder sign-off on goals before writing tasks Goals drive task selection. If goals shift after tasks are written, you may have to rewrite the entire discussion guide. Locking goals early is the highest-leverage step in the planning phase. | D20: Dovetail: Customer Research Guide
C21: Common mistake: writing goals that are really just a list of features to evaluate ('test the navigation, the search, and the filters'). Push back by asking: what decision will that information inform?
B23: Writing Strong Test Tasks
C24: Practical Guidelines | D24: Further Reading
C25: 1. Use scenario framing, not instructions Instead of 'Click on the profile menu and change your name', write 'You have just moved. Please update your account to reflect your new address.' Scenarios activate realistic mental models. | D25: NNG: Writing Usability Test Tasks
C26: 2. Never embed the answer in the task Avoid using the exact UI label in the task wording. If the button says 'Create an account, don't write 'Find a way to create a new account'. This tests recognition, not usability. | D26: NNG: Priming in Usability Testing
C27: 3. Make tasks realistic and specific Vague tasks ('explore the site') produce vague data. Ground each task in a concrete goal a real user would have: a program to find, an amount to enter, a form to submit. | D27: Usability.gov: Task Development
C28: 4. Pilot every task before fieldwork Run each task with one internal colleague who matches the participant profile. You will immediately find ambiguous wording, missing pre-conditions, and tasks that are too long. | D28: NNG: Pilot Testing
C29: 5. Set a realistic time limit per task Time limits keep sessions on schedule and provide a natural stopping condition. A common rule of thumb: if a task takes longer than 5 minutes in a pilot, either simplify it or split it in two. | D29: Maze: Usability Test Structure
C30: 6. Sequence tasks to mirror real user journeys Where possible, order tasks so they follow a logical progression (e.g., search then view then purchase). Artificial task sequences can confuse participants and create carry-over effects. | D30: IxDF: Test Task Sequencing
B32: Recruitment & Participant Selection
C33: Practical Guidelines | D33: Further Reading
C34: 1. Define screener criteria from your testing goals Work backwards from your goals: what must be true about a participant for their data to be valid? List must-haves (e.g., active smartphone user) and nice-to-haves separately to avoid over-constraining recruitment. | D34: NNG: Recruiting Usability Participants
C35: 2. 5 participants reveal ~85% of usability issues Nielsen's original finding still holds for qualitative discovery studies. For quantitative benchmarking or multiple distinct user groups, sample sizes of 20+ are more appropriate. | D35: NNG: How Many Test Users?
C36: 3. Recruit 20% more participants than you need No-shows, late cancellations, and disqualifications are common. Buffer your recruitment target accordingly. For 10 sessions, recruit at least 12 and confirm the day before. | D36: UserZoom: Recruiting for Research
C37: 4. Spread sessions across different times of day If recruiting working professionals, morning-only slots will bias your sample toward certain roles. Offer morning, midday, and afternoon options to maximise diversity. | D37: Dovetail: Recruitment Best Practices
C38: 5. Avoid friends, family, and colleagues People who know the product team are less likely to give candid feedback and more likely to be forgiving of issues. Use external panels, CRM outreach, or intercept recruiting instead. | D38: NNG: Participant Selection
C39: 6. Document no-shows and replacements Track who was recruited, who attended, and why anyone was excluded. This data protects you if stakeholders later question the representativeness of your sample. | D39: ResearchOps: Participant Management
C40: Screener design tip: include one or two disqualifying questions that participants cannot easily game. For example, instead of asking 'Do you shop online?' (everyone says yes), ask how many online purchases they made in the last month.
B42: Collecting & Recording Session Data
B43: Corresponds to: Data tab
C44: Practical Guidelines | D44: Further Reading
C45: 1. Use the success codes consistently across all sessions Brief all observers before the first session on exactly what constitutes Success vs. Partial Fail vs. Give Up. Inconsistent coding makes cross-participant comparisons unreliable. | D45: NNG: Scoring Usability Tests
...
