Workbook

Sheet Kickoff Questions
B1: USABILITY TEST KICKOFF · Questions to Scope Your Study
B2: Use these questions to guide your kickoff meeting with product owners and stakeholders before designing your study.
B3: The 'Your Notes' column is for capturing answers, commitments, or follow-up actions during or after the meeting.
C5: Question | D5: Your Notes
C6: Background & Business Context
B7: › | C7: What is this product or feature, and who is it designed for?
B8: › | C8: What problem does it solve for the user? What problem does it solve for the business?
B9: › | C9: Where does this sit in the product lifecycle — pre-launch validation, a post-launch audit, or something else?
B10: › | C10: What prompted this research request right now? Was there a specific incident, metric, complaint, or upcoming deadline?
B11: › | C11: Has this product or feature been tested before? If so, what were the findings, and what changed since then?
B12: › | C12: Are there competing internal priorities or other research streams we should be aware of that might affect timelines or access to participants?
C14: Research Goals & Questions
B15: › | C15: What are the two or three most important things you need to learn from this study?
B16: › | C16: If you could only answer one question from this test, what would it be?
B17: › | C17: What decisions will be made with the output of this research? Who will be making those decisions?
B18: › | C18: Are there any hypotheses you're already working with — things you suspect are true but need to validate or disprove?
B19: › | C19: Are there any areas of the product you specifically want to include or exclude from testing?
B20: › | C20: Is there anything you're worried we might find?
B21: › | C21: What does 'success' look like for this research engagement — what would make stakeholders feel it was worth doing?
C23: Users & Participants
B24: › | C24: Who is the primary target user for this product or feature?
B25: › | C25: Are there distinct user segments or personas we should account for? Should we test all of them, or prioritize one?
B26: › | C26: What level of prior experience with this product should participants have — first-time users, occasional users, power users, or a mix?
B27: › | C27: Are there any technical or domain knowledge requirements for participants (e.g., must be a healthcare professional, must manage a team of 5+)?
B28: › | C28: What devices do your users typically use — desktop, mobile, tablet? Is there a known split?
B29: › | C29: What is the geographic and language distribution of your users? Should the test reflect that?
B30: › | C30: Are there demographics that are particularly important to include or exclude (e.g., accessibility needs, age ranges, tech literacy)?
B31: › | C31: Do you have access to an existing user panel or CRM we can recruit from, or will we be recruiting externally?
B32: › | C32: Are there any legal or compliance constraints around who can participate (e.g., minors, regulated industries)?
B33: › | C33: How many participants are you expecting — and are you open to a recommendation on sample size?
C35: Scope & Tasks
B36: › | C36: What are the specific tasks or user journeys you want us to test?
B37: › | C37: Are these tasks based on actual observed user behaviour, or are they assumed flows?
B38: › | C38: What is the starting point for each task — a specific URL, a particular app state, a logged-in or logged-out experience?
B39: › | C39: Are there prerequisite conditions for any tasks (e.g., the user must have already created an account, added items to a cart)?
B40: › | C40: Are there tasks you want to include for benchmarking purposes — things you've tested before and want to track over time?
B41: › | C41: What does successful completion of each task look like? Is it binary, or is partial completion meaningful?
B42: › | C42: Should we be testing the current live product, a prototype, or a staging environment?
B43: › | C43: If it's a prototype — how complete is it? Are there dead ends, missing states, or known gaps we should know about?
B44: › | C44: Are there any flows that are broken, incomplete, or should be avoided during testing?
...

Sheet Summary
B1: USABILITY TEST PLAN · Summary Dashboard
B2: Auto-calculated metrics pulled from the Data tab. Fill in Data tab first.
B3: TASK COMPLETION RATES (by Success Code)
B4: Metric | C4: Task 1 | D4: Task 2 | E4: Task 3 | F4: Task 4 | G4: Task 5
B5: Success | C5: =COUNTIF(Data!D5:D14,"Success") -> 0 | D5: =COUNTIF(Data!G5:G14,"Success") -> 0 | E5: =COUNTIF(Data!J5:J14,"Success") -> 0 | F5: =COUNTIF(Data!M5:M14,"Success") -> 0 | G5: =COUNTIF(Data!P5:P14,"Success") -> 0
B6: ⚠ Partial Fail | C6: =COUNTIF(Data!D5:D14,"Partial Fail") -> 0 | D6: =COUNTIF(Data!G5:G14,"Partial Fail") -> 0 | E6: =COUNTIF(Data!J5:J14,"Partial Fail") -> 0 | F6: =COUNTIF(Data!M5:M14,"Partial Fail") -> 0 | G6: =COUNTIF(Data!P5:P14,"Partial Fail") -> 0
B7: Fail | C7: =COUNTIF(Data!D5:D14,"Fail") -> 0 | D7: =COUNTIF(Data!G5:G14,"Fail") -> 0 | E7: =COUNTIF(Data!J5:J14,"Fail") -> 0 | F7: =COUNTIF(Data!M5:M14,"Fail") -> 0 | G7: =COUNTIF(Data!P5:P14,"Fail") -> 0
B8: ⏱ Time Limit | C8: =COUNTIF(Data!D5:D14,"Time Limit") -> 0 | D8: =COUNTIF(Data!G5:G14,"Time Limit") -> 0 | E8: =COUNTIF(Data!J5:J14,"Time Limit") -> 0 | F8: =COUNTIF(Data!M5:M14,"Time Limit") -> 0 | G8: =COUNTIF(Data!P5:P14,"Time Limit") -> 0
B9: Give Up | C9: =COUNTIF(Data!D5:D14,"Give Up") -> 0 | D9: =COUNTIF(Data!G5:G14,"Give Up") -> 0 | E9: =COUNTIF(Data!J5:J14,"Give Up") -> 0 | F9: =COUNTIF(Data!M5:M14,"Give Up") -> 0 | G9: =COUNTIF(Data!P5:P14,"Give Up") -> 0
B10: Technical Issues | C10: =COUNTIF(Data!D5:D14,"Technical Issues") -> 0 | D10: =COUNTIF(Data!G5:G14,"Technical Issues") -> 0 | E10: =COUNTIF(Data!J5:J14,"Technical Issues") -> 0 | F10: =COUNTIF(Data!M5:M14,"Technical Issues") -> 0 | G10: =COUNTIF(Data!P5:P14,"Technical Issues") -> 0
B11: Other | C11: =COUNTIF(Data!D5:D14,"Other") -> 0 | D11: =COUNTIF(Data!G5:G14,"Other") -> 0 | E11: =COUNTIF(Data!J5:J14,"Other") -> 0 | F11: =COUNTIF(Data!M5:M14,"Other") -> 0 | G11: =COUNTIF(Data!P5:P14,"Other") -> 0
B12: Total Recorded | C12: =COUNTA(Data!D5:D14) -> 0 | D12: =COUNTA(Data!G5:G14) -> 0 | E12: =COUNTA(Data!J5:J14) -> 0 | F12: =COUNTA(Data!M5:M14) -> 0 | G12: =COUNTA(Data!P5:P14) -> 0
B13: Success Rate | C13: =IFERROR(COUNTIF(Data!D5:D14,"Success")/COUNTA(Data!D5:D14),"") | D13: =IFERROR(COUNTIF(Data!G5:G14,"Success")/COUNTA(Data!G5:G14),"") | E13: =IFERROR(COUNTIF(Data!J5:J14,"Success")/COUNTA(Data!J5:J14),"") | F13: =IFERROR(COUNTIF(Data!M5:M14,"Success")/COUNTA(Data!M5:M14),"") | G13: =IFERROR(COUNTIF(Data!P5:P14,"Success")/COUNTA(Data!P5:P14),"")
B15: TOP-LEVEL FINDINGS SUMMARY
B16: Most Critical Issue
B17: Most Impacted Task
B18: Overall Success Rate | C18: =IFERROR(AVERAGE(C14:G14),"")
B19: Key Recommendation 1
B20: Key Recommendation 2
B21: Key Recommendation 3
B22: Follow-up Questions
B23: Next Steps

Sheet Study Goals
B1: USABILITY TEST PLAN · Study Goals
B2: Define the objectives for this usability study and how each goal will be measured.
B3: STUDY METADATA
B4: Study Title
B5: Product / Feature
B6: Research Lead
B7: Date(s) of Testing
B8: Methodology
B10: STUDY GOALS
B11: # | C11: Research Goal | D11: Why It Matters | E11: How It Will Be Measured | F11: Priority
B12: 1 | C12: Identify usability issues in the main task flow | D12: Core functionality must be intuitive for users | E12: Usability issues found; time on task | F12: High
B13: 2 | C13: Assess learnability for first-time users | D13: Product targets non-technical audience | E13: Task success rate; qualitative feedback | F13: High
B14: 3 | C14: Evaluate satisfaction with UI language & labels | D14: Confusing labels increase support load | E14: Verbal think-aloud; post-task ratings | F14: Medium
B15: 4 | C15: Benchmark task completion time | D15: Establishes baseline for future tests | E15: Time on task per scenario | F15: Medium
B16: 5
B18: MEASUREMENT METHODS · Reference
B19: Metric | C19: Description | D19: When to Use
B20: Time on Task | C20: Clock time from task start to end (success or stop) | D20: Efficiency benchmarking; identifying slow flows
B21: Task Success Rate | C21: % of participants who complete task successfully | D21: Core usability health metric
B22: Error Rate | C22: # of errors / incorrect actions per task attempt | D22: Identifying misleading UI elements
B23: Think-Aloud Feedback | C23: Verbal commentary captured during the session | D23: Understanding mental models & confusion points
B24: Post-Task Rating | C24: Participant self-report on ease (e.g. SEQ 1–7) | D24: Perceived difficulty vs observed difficulty
B25: Post-Study Questionnaire | C25: SUS, UMUX-Lite, or custom satisfaction survey | D25: Overall satisfaction & benchmarking

Sheet Tasks
B1: USABILITY TEST PLAN · Tasks & Scenarios
B2: Define each task scenario, the starting state, success criteria, and researcher notes.
B3: Task # | C3: Task Title | D3: Task Text (shown to participant) | E3: Success Criteria | F3: Starting State / Pre-conditions | G3: Time Limit (mm:ss) | H3: Difficulty Estimate | I3: Researcher Notes
B4: T1 | C4: Find a product | D4: Starting from the homepage, find the product called "[Product Name]" and add it to your cart. | E4: Participant adds correct item to cart | F4: Logged-out homepage | G4: 03:00 | H4: Easy
B5: T2 | C5: Create an account | D5: Please create a new account using your email address. | E5: Account created; confirmation screen shown | F5: Homepage, logged out | G5: 05:00 | H5: Medium | I5: Watch for confusion on password rules
B6: T3 | C6: Update profile | D6: You have just logged in. Please update your display name to 'Test User'. | E6: Display name updated and saved | F6: Logged-in dashboard | G6: 02:00 | H6: Easy
B7: T4 | C7: Complete checkout | D7: Please complete the purchase of the item in your cart. | E7: Order confirmation page reached | F7: Cart with 1 item | G7: 05:00 | H7: Hard | I7: Note any payment form issues
B8: T5 | C8: Find order history | D8: You placed an order last week. Please find that order and check its current status. | E8: Order status page viewed | F8: Logged-in account | G8: 03:00 | H8: Medium
B13: FACILITATOR SCRIPT GUIDE
B14: Introduction | C14: Welcome the participant, explain the think-aloud protocol, and clarify that you are testing the product, not them. Obtain consent.
B15: Warm-up | C15: Ask 2–3 background questions (e.g. device usage habits) to ease the participant in before tasks begin.
B16: Task Delivery | C16: Read each task aloud and hand the participant the printed/on-screen task card. Do not answer navigational questions — redirect: 'What would you do if I weren't here?'
B17: Wrap-up | C17: Administer post-study questionnaire. Ask any debrief questions. Thank the participant and explain next steps.

Sheet Participants
B1: USABILITY TEST PLAN · Participants
B2: Section A: Define screening criteria. Section B: Record recruited participant details.
B3: SECTION A · Desired Participant Profile & Screening Criteria
B4: Target User Group | C4: Primary users of the product; existing customers or qualified prospects
B5: Age Range | C5: 18–55
B6: Tech Proficiency | C6: Comfortable using smartphones and web browsers; not IT professionals
B7: Device Requirement | C7: Must own and regularly use a smartphone (iOS or Android)
B8: Language | C8: English (native or fluent)
B9: Location | C9: Canada or United States
B10: Exclusion Criteria | C10: Employees of [Company]; anyone who has participated in a test in last 6 months
B11: Sample Size | C11: 10 participants (minimum 5 for qualitative saturation)
B12: Incentive | C12: $XX gift card or equivalent
B14: SECTION B · Recruited Participant Details
B15: P # | C15: Name / Code | D15: Age | E15: Country | F15: Device Type | G15: OS | H15: Language | I15: Tech Proficiency | J15: Recruited By | K15: Session Date & Time | L15: Notes
B16: P01
B17: P02
B18: P03
B19: P04
B20: P05
B21: P06
B22: P07
B23: P08
B24: P09
B25: P10
B26: P11

Sheet Data
B1: USABILITY TEST PLAN · Session Data
B2: Record each participant's performance per task. Use the Success Code dropdown for outcome classification.
C3: TASK 1 | F3: TASK 2 | I3: TASK 3 | L3: TASK 4 | O3: TASK 5
B4: P # | C4: Time on Task | D4: Success Code | E4: Observations / Notes | F4: Time on Task | G4: Success Code | H4: Observations / Notes | I4: Time on Task | J4: Success Code | K4: Observations / Notes | L4: Time on Task | M4: Success Code | N4: Observations / Notes | O4: Time on Task | P4: Success Code | Q4: Observations / Notes
B5: P01
B6: P02
B7: P03
B8: P04
B9: P05
B10: P06
B11: P07
B12: P08
B13: P09
B14: P10
B15: P11
B17: SUCCESS CODE LEGEND
B18: Success | C18: Participant completed the task fully and correctly within the time limit. | F18: Partial Fail | G18: Participant completed the task but with significant errors, help, or workarounds.
B19: Fail | C19: Participant did not complete the task and gave an incorrect outcome. | F19: Time Limit | G19: Participant ran out of time before completing the task.
B20: Give Up | C20: Participant abandoned the task of their own volition. | F20: Technical Issues | G20: Session interrupted by a technical problem unrelated to the participant.
B21: Other | C21: Does not fit any other category. Add details in Observations.

Sheet Analysis
B1: USABILITY TEST PLAN · Analysis & Recommendations
B2: Synthesize findings per task. Identify key issues, severity, and actionable recommendations.
B3: Analysis Dimension | C3: Task 1 | D3: Task 2 | E3: Task 3 | F3: Task 4 | G3: Task 5
B4: Key Usability Issues Observed | C4: List specific problems seen across participants. | D4: List specific problems seen across participants. | E4: List specific problems seen across participants. | F4: List specific problems seen across participants. | G4: List specific problems seen across participants.
B5: Frequency
B6: Severity
B7: Root Cause (Hypothesis)
B8: Supporting Quotes / Observations
B9: Recommendations
B10: Priority for Fix
B11: Effort Estimate
B12: Additional Notes
B14: SEVERITY RATING GUIDE
B15: Severity | C15: Definition | D15: Frequency Threshold | E15: Recommended Action
B16: Critical | C16: Prevents task completion; user cannot proceed | D16: ≥ 50% of participants | E16: Fix before launch
B17: High | C17: Causes significant struggle; workaround is painful | D17: ≥ 30% of participants | E17: Fix in next sprint
B18: Medium | C18: Causes confusion or delay but task is completable | D18: ≥ 20% of participants | E18: Schedule for roadmap
B19: Low | C19: Minor annoyance; cosmetic or edge-case issue | D19: < 20% of participants | E19: Backlog / nice-to-have

Sheet Help & Guidance
B1: HELP & GUIDANCE · Best Practices for Usability Testing
B2: A reference guide for each phase of your usability test — practical tips and curated external reading.
B3: All links open in your browser. Tip: use Ctrl+Click (Windows) or Cmd+Click (Mac) to follow hyperlinks in Excel.
B5: Running an Effective Kickoff Meeting
B6: Corresponds to: Kickoff Questions tab
C7: Practical Guidelines | D7: Further Reading
C8: 1. Start with the decision, not the feature Before diving into tasks to test, anchor the whole conversation on what decision this research will inform. If stakeholders can't name one, that is the first problem to solve. | D8: NNG: Stakeholder Buy-In for UX Research
C9: 2. Send questions in advance Share the kickoff question list 48 hours early. Stakeholders arrive better prepared, meetings run shorter, and you get more considered answers rather than reactive ones. | D9: NNG: Research Learning Spirals
C10: 3. Surface disagreements early If the room can't agree on the top priority research question, document both views rather than forcing false consensus. Unresolved disagreements surface during analysis — better to name them now. | D10: UX Collective: Aligning Stakeholders
C11: 4. Ask 'what would change your mind?' For each goal, ask stakeholders what evidence would cause them to change course. This reveals which questions are genuinely open and which are fishing for validation. | D11: Maze: Research Ops Handbook
C12: 5. Clarify sign-off chains before you leave Confirm who approves the screener, discussion guide, and final report — and in what order. A missing approval can delay fieldwork by weeks. | D12: ResearchOps Community
C13: 6. Record or take structured notes Assign a dedicated note-taker so the facilitator can stay focused. Review notes within 24 hours while memory is fresh and send a summary back to stakeholders to confirm alignment. | D13: NNG: Documenting UX Research
C14: Pro tip: The most revealing kickoff question is often 'What are you worried we might find?' — it surfaces assumptions worth testing and builds trust by showing you are not just there to confirm what stakeholders already believe.
B16: Defining Effective Study Goals
B17: Corresponds to: Study Goals tab
C18: Practical Guidelines | D18: Further Reading
C19: 1. Distinguish research goals from business goals A business goal is 'reduce churn'. A research goal is 'understand why users abandon the onboarding flow after step 3'. Usability tests answer research questions, not business metrics directly. | D19: NNG: Research Questions vs. Business Goals
C20: 2. Limit yourself to 3-5 goals per study More than five goals usually means the study is trying to do too much. Prioritise ruthlessly. A focused study with clear answers is worth far more than a sprawling one with ambiguous takeaways. | D20: Usability.gov: Planning a Usability Test
C21: 3. Write goals as questions, not statements 'Evaluate the checkout flow' is a topic. 'Can users complete a purchase without assistance in under 4 minutes?' is a testable goal. The question form forces you to think about what evidence you need. | D21: IxDF: Formulating UX Research Goals
C22: 4. Pair every goal with a measurement method For each goal, define up front how you will know if it has been met — task success rate, time on task, error count, qualitative theme, or a scale score. Unmeasured goals are just intentions. | D22: NNG: Measuring Usability
C23: 5. Include at least one benchmarking goal if re-testing If this is not the first test of the product, carry over at least one metric from the previous study. Trend data is far more persuasive with engineering and product leadership than a single snapshot. | D23: NNG: Benchmarking UX
C24: 6. Get stakeholder sign-off on goals before writing tasks Goals drive task selection. If goals shift after tasks are written, you may have to rewrite the entire discussion guide. Locking goals early is the highest-leverage step in the planning phase. | D24: UX Research Field Guide (Dovetail)
C25: Common mistake: writing goals that are really just a list of features to evaluate ('test the navigation, the search, and the filters'). Push back by asking: what decision will that information inform?
B27: Writing Strong Test Tasks
B28: Corresponds to: Tasks tab
C29: Practical Guidelines | D29: Further Reading
C30: 1. Use scenario framing, not instructions Instead of 'Click on the profile menu and change your name', write 'You have just moved. Please update your account to reflect your new address.' Scenarios activate realistic mental models. | D30: NNG: Writing Usability Test Tasks
C31: 2. Never embed the answer in the task Avoid using the exact UI label in the task wording. If the button says 'Manage Subscription', don't write 'Find the Manage Subscription button'. This tests recognition, not usability. | D31: NNG: Priming in Usability Testing
C32: 3. Make tasks realistic and specific Vague tasks ('explore the site') produce vague data. Ground each task in a concrete goal a real user would have: a product to find, an amount to enter, a form to submit. | D32: Usability.gov: Task Development
C33: 4. Pilot every task before fieldwork Run each task with one internal colleague who matches the participant profile. You will immediately find ambiguous wording, missing pre-conditions, and tasks that are too long. | D33: NNG: Pilot Testing
C34: 5. Set a realistic time limit per task Time limits keep sessions on schedule and provide a natural stopping condition. A common rule of thumb: if a task takes longer than 5 minutes in a pilot, either simplify it or split it in two. | D34: Maze: Usability Test Structure
C35: 6. Sequence tasks to mirror real user journeys Where possible, order tasks so they follow a logical progression (e.g., search then view then purchase). Artificial task sequences can confuse participants and create carry-over effects. | D35: IxDF: Test Task Sequencing
C36: A useful self-check: read the task aloud and ask yourself whether a participant could succeed without ever finding the UI element you intended. If yes, the task is too open-ended. If the only path is the one you designed, it may be too narrow.
B38: Recruitment & Participant Selection
B39: Corresponds to: Participants tab
C40: Practical Guidelines | D40: Further Reading
C41: 1. Define screener criteria from your research goals Work backwards from your goals: what must be true about a participant for their data to be valid? List must-haves (e.g., active smartphone user) and nice-to-haves separately to avoid over-constraining recruitment. | D41: NNG: Recruiting Usability Participants
C42: 2. 5 participants reveal ~85% of usability issues Nielsen's original finding still holds for qualitative discovery studies. For quantitative benchmarking or multiple distinct user groups, sample sizes of 20+ are more appropriate. | D42: NNG: How Many Test Users?
C43: 3. Recruit 20% more participants than you need No-shows, late cancellations, and disqualifications are common. Buffer your recruitment target accordingly. For 10 sessions, recruit at least 12 and confirm the day before. | D43: UserZoom: Recruiting for Research
C44: 4. Spread sessions across different times of day If recruiting working professionals, morning-only slots will bias your sample toward certain roles. Offer morning, midday, and afternoon options to maximise diversity. | D44: Dovetail: Recruitment Best Practices
...
